Workbook
Name Measures: '[1]Scorecard Data'!$B$3:$B$132

Sheet Cover Page
E11: ENTERPRISE VALUATION
D29: Date: July 06, 2021 | E29: Recommendation: BUY | F29: Sector: Pharmaceuticals & Chemicals
D30: Current Price: BDT 217.9 (USD 2.58) | E30: Target Price: BDT 281.09 (USD 3.32) | F30: DSE: SQURPHARMA
E31: Upside Potential: 29.00%

Sheet Balance Sheet
A1: SQUARE PHARMACEUTICALS LTD.
A2: Consolidated Statement of Financial Position
B3: 2015-2016 | C3: 2016-2017 | D3: 2017-2018 | E3: 2018-2019 | F3: 2019-2020
A4: ASSETS
A5: Non-current assets
A6: Property, plant and equipment - Carrying Value | B6: 18848282139 | C6: 19323568164 | D6: 20545437633 | E6: 20853956270 | F6: 20873698301
A7: Investment - long term | B7: 555873893 | C7: 588808565 | D7: 940754391 | E7: 655408674 | F7: 2792000884
A8: Investment - associates undertaking | B8: 6764511325 | C8: 7504636420 | D8: 8454064733 | E8: 9211605860 | F8: 8077472192
A9: Investment in marketable securities (Fair Value) | B9: 1071735442 | C9: 1938209078 | D9: 2891208537 | E9: 3013439734 | F9: 2691892867
A10: Pre-operating expenses | F10: 774363
A11: Total Non-current Assets | B11: =SUM(B6:B9) -> 27240402799 | C11: =SUM(C6:C9) -> 29355222227 | D11: =SUM(D6:D9) -> 32831465294 | E11: =SUM(E6:E9) -> 33734410538 | F11: =SUM(F6:F10) -> 34435838607
A13: Current Assets
A14: Inventories | B14: 3694711088 | C14: 3730808243 | D14: 4432935118 | E14: 4596512673 | F14: 5687406329
A15: Trade and other receivables | B15: 1335829914 | C15: 2204014900 | D15: 1615544248 | E15: 1561818167 | F15: 1520300337
A16: Advances, deposits and prepayments | B16: 1131340560 | C16: 1450936735 | D16: 2280668747 | E16: 2312201184 | F16: 2727928252
A17: Short Term Loan | B17: 2378929958 | C17: 21386290 | D17: 3131975363 | E17: 2937071066 | F17: 4884338757
A18: Cash and cash equivalents | B18: 8522555131 | C18: 15768683854 | D18: 16980412765 | E18: 27004038946 | F18: 32564329438
A19: Total Current Assets | B19: =SUM(B14:B18) -> 17063366651 | C19: =SUM(C14:C18) -> 23175830022 | D19: =SUM(D14:D18) -> 28441536241 | E19: =SUM(E14:E18) -> 38411642036 | F19: =SUM(F14:F18) -> 47384303113
A21: TOTAL ASSETS | B21: =B11+B19 -> 44303769450 | C21: =C11+C19 -> 52531052249 | D21: =D11+D19 -> 61273001535 | E21: =E11+E19 -> 72146052574 | F21: =F11+F19 -> 81820141720
A23: EQUITY AND LIABILITIES
A24: Share capital | B24: 6235865460 | C24: 6859452000 | D24: 7373910900 | E24: 7890084660 | F24: 8442390580
A25: Share premium | B25: 2035465000 | C25: 2035465000 | D25: 2035465000 | E25: 2035465000 | F25: 2035465000
A26: General Reserve | B26: 105878200 | C26: 105878200 | D26: 105878200 | E26: 105878200 | F26: 105878200
A27: Tax Exemption Reserve | B27: 324011067 | C27: 852508043 | D27: 1949557722 | E27: 2211743936 | F27: 2211743936
A28: Gain on marketable securities (Unrealized) | B28: 266786579 | C28: 596561713 | D28: 192272252 | E28: 145585283 | F28: -452626946
A29: Cumulative Translation Adujustment | E29: -939072 | F29: -18078434
A30: Retained earnings | B30: 31587049056 | C30: 38577835254 | D30: 46159482757 | E30: 55492799165 | F30: 64981071577
A31: Non-controlling interests | B31: 2098295 | C31: 12674141 | D31: 24901060
A32: TOTAL EQUITY | B32: =SUM(B24:B30) -> 40555055362 | C32: =SUM(C24:C30) -> 49027700210 | D32: =SUM(D24:D30) -> 57816566831 | E32: =SUM(E24:E30) -> 67880617172 | F32: =SUM(F24:F30) -> 77305843913
A34: Non-current Liability
A35: Deferred tax liability | B35: 1054498262 | C35: 1129233846 | D35: 1231133152 | E35: 1294346873 | F35: 1272750021
A36: Total Non-current Liability | B36: =B35 -> 1054498262 | C36: =C35 -> 1129233846 | D36: =D35 -> 1231133152 | E36: =E35 -> 1294346873 | F36: =F35 -> 1272750021
A38: Current Liability
A39: Short term loan | B39: 2693932
A40: Trade creditors | B40: 693982698 | C40: 843937277 | D40: 524676136 | E40: 716988428 | F40: 553785496
A41: Liabilities for expenses | B41: 42871218 | C41: 27576542 | D41: 89665092 | E41: 239913331 | F41: 128998444
A42: Liabilities for other finances | B42: 1952569683 | C42: 1489930233 | D42: 1586059264 | E42: 2014186770 | F42: 2558763846
A43: Total Current Liability | B43: =SUM(B39:B42) -> 2692117531 | C43: =SUM(C39:C42) -> 2361444052 | D43: =SUM(D39:D42) -> 2200400492 | E43: =SUM(E39:E42) -> 2971088529 | F43: =SUM(F39:F42) -> 3241547786
A45: TOTAL LIABILITY | B45: =B36+B43 -> 3746615793 | C45: =C36+C43 -> 3490677898 | D45: =D36+D43 -> 3431533644 | E45: =E36+E43 -> 4265435402 | F45: =F36+F43 -> 4514297807
A47: TOTAL EQUITY AND LIABILITY | B47: =B45+B32+B31 -> 44303769450 | C47: =C45+C32+C31 -> 52531052249 | D47: =D45+D32+D31 -> 61273001535 | E47: =E45+E32+E31 -> 72146052574 | F47: =F45+F32+F31 -> 81820141720

Sheet Income Statement
A1: SQUARE PHARMACEUTICALS LTD.
A2: Consolidated Statement of Profit or Loss and Other Comprehensive Income
B3: 2015-2016 | C3: 2016-2017 | D3: 2017-2018 | E3: 2018-2019 | F3: 2019-2020
A5: Gross revenue | B5: 38325600166 | C5: 42284675530 | D5: 45886959303 | E5: 50866867352 | F5: 52926218655
A6: Less: Value Added Tax | B6: 5251839594 | C6: 5741535424 | D6: 6233127665 | E6: -6833233083 | F6: 7049769814
A7: Net revenue | B7: =B5-B6 -> 33073760572 | C7: =C5-C6 -> 36543140106 | D7: =D5-D6 -> 39653831638 | E7: =SUM(E5:E6) -> 44033634269 | F7: =F5-F6 -> 45876448841
A8: Cost of sales | B8: -17082336657 | C8: -18274858914 | D8: -20089819913 | E8: -22091384351 | F8: -22536669960
A9: Gross profit | B9: =SUM(B7:B8) -> 15991423915 | C9: =SUM(C7:C8) -> 18268281192 | D9: =SUM(D7:D8) -> 19564011725 | E9: =SUM(E7:E8) -> 21942249918 | F9: =SUM(F7:F8) -> 23339778881
A11: Selling & distribution expenses | B11: -4349841995 | C11: -5056851926 | D11: -5751408276 | E11: -6603747456 | F11: -7382790764
A12: Aministrative expenses | B12: -845013243 | C12: -915210284 | D12: -1031567251 | E12: -1195957909 | F12: -1226459468
A13: Finance Cost | B13: -5299871 | C13: -154389 | D13: -93599 | E13: -95196 | F13: -107090
A14: Operating profit | B14: =SUM(B9,B11:B13) -> 10791268806 | C14: =SUM(C9,C11:C13) -> 12296064593 | D14: =SUM(D9,D11:D13) -> 12780942599 | E14: =SUM(E9,E11:E13) -> 14142449357 | F14: =SUM(F9,F11:F13) -> 14730421559
A16: Other Income | B16: 657143316 | C16: 1093575634 | D16: 1768094011 | E16: 2310360094 | F16: 3126430063
A17: Profit before contribution to workers participantion fund | B17: =SUM(B14,B16) -> 11448412122 | C17: =SUM(C14,C16) -> 13389640227 | D17: =SUM(D14,D16) -> 14549036610 | E17: =SUM(E14,E16) -> 16452809451 | F17: =SUM(F14,F16) -> 17856851622
A18: Allocation for WPPF | B18: -545162482 | C18: -646577651 | D18: -701097850 | E18: -791921561 | F18: -859269098
A19: Profit before tax | B19: =SUM(B17,B18) -> 10903249640 | C19: =SUM(C17,C18) -> 12743062576 | D19: =SUM(D17,D18) -> 13847938760 | E19: =SUM(E17,E18) -> 15660887890 | F19: =SUM(F17,F18) -> 16997582524
A21: Tax expenses
A22: Income tax expenses - Current | B22: -2389605742 | C22: -2949150787 | D22: -3255148172 | E22: -3876979330 | F22: -4251005177
A23: Income tax expenses - Deferred | B23: -227100343 | C23: -74735584 | D23: -101899306 | E23: -63213721 | F23: 21596852
A24: Total tax expense | B24: =SUM(B22:B23) -> -2616706085 | C24: =SUM(C22:C23) -> -3023886371 | D24: =SUM(D22:D23) -> -3357047478 | E24: =SUM(E22:E23) -> -3940193051 | F24: =SUM(F22:F23) -> -4229408325
A25: Profit after tax | B25: =SUM(B19,B24) -> 8286543555 | C25: =SUM(C19,C24) -> 9719176205 | D25: =SUM(D19,D24) -> 10490891282 | E25: =SUM(E19,E24) -> 11720694839 | F25: =SUM(F19,F24) -> 12768174199
A26: Profit/(loss) from associate undertakings | B26: 916314929 | C26: 928615539 | D26: 1115299919 | E26: 931706302 | F26: 586239690
A27: Net profit after tax | B27: =SUM(B25,B26) -> 9202858484 | C27: =SUM(C25,C26) -> 10647791744 | D27: =SUM(D25,D26) -> 11606191201 | E27: =SUM(E25,E26) -> 12652401141 | F27: =SUM(F25,F26) -> 13354413889
A28: Other Comprehensive Income:
A29: Gain/(loss) on marketable securities (unrealized) | B29: -3169514 | C29: 329775134 | D29: -404289461 | E29: -46686969 | F29: -598212229
A30: Cumulative translation adjustment | E30: -939072 | F30: -17139363
A31: Total comprehensive income for the year | B31: =SUM(B27:B29) -> 9199688970 | C31: =SUM(C27:C29) -> 10977566878 | D31: =SUM(D27:D29) -> 11201901740 | E31: =SUM(E27:E30) -> 12604775100 | F31: =SUM(F27:F30) -> 12739062297
A33: Profit attributable to:
A34: Owners of the company | B34: 9198977093 | C34: 10637215898 | D34: 11593964282 | E34: 12645724268 | F34: 13354413889
A35: Non controlling interest | B35: 3881391 | C35: 10575846 | D35: 12226919 | E35: 6676873
B36: =SUM(B34:B35) -> 9202858484 | C36: =SUM(C34:C35) -> 10647791744 | D36: =SUM(D34:D35) -> 11606191201 | E36: =SUM(E34:E35) -> 12652401141 | F36: =SUM(F34:F35) -> 13354413889
A37: Total comprehensive income attributable to:
A38: Owners of the company | B38: 9195807579 | C38: 10966991032 | D38: 11189674821 | E38: 12598199525 | F38: 12739062297
A39: Non controlling interest | B39: 3881391 | C39: 10575846 | D39: 12226919 | E39: 6575575
B40: =B38+B39 -> 9199688970 | C40: =C38+C39 -> 10977566878 | D40: =D38+D39 -> 11201901740 | E40: =E38+E39 -> 12604775100 | F40: =F38+F39 -> 12739062297
A42: Earnings per share (EPS) | B42: 13.41 | C42: 15.51 | D42: 15.72 | E42: 16.03 | F42: 15.82

Sheet Cashflow Statement
A1: SQUARE PHARMACEUTICALS LTD.
A2: Consolidated Statement of Cash Flows
B3: 2015-2016 | C3: 2016-2017 | D3: 2017-2018 | E3: 2018-2019 | F3: 2019-2020
A5: Cash flows from operating activities
A6: RECEIPTS:
A7: Collection from sales | B7: 37930633639 | C7: 41454805384 | D7: 46195703039 | E7: 51074051570 | F7: 52909065970
A8: Exchange fluctuation gain | D8: 83957932 | E8: 4868172 | F8: 2216358
A9: others | B9: 112691000 | C9: 201824119 | D9: 141124951 | E9: 82804049 | F9: 33621327
B10: =SUM(B7:B9) -> 38043324639 | C10: =SUM(C7:C9) -> 41656629503 | D10: =SUM(D7:D9) -> 46420785922 | E10: =SUM(E7:E9) -> 51161723791 | F10: =SUM(F7:F9) -> 52944903655
A11: PAYMENTS:
A12: Purchase of raw and packing materials | B12: 12055106675 | C12: 12448372527 | D12: 14895596440 | E12: 15619769171 | F12: 17024316320
A13: Manufacturing and operating expenses | B13: 8466672238 | C13: 9708309353 | D13: 11222587267 | E13: 11773729181 | F13: 13446602730
A14: Value added tax | B14: 5251839594 | C14: 5741535424 | D14: 6233127665 | E14: 6833233083 | F14: 7049769814
A15: Finance Cost | B15: 5299871 | C15: 154389 | D15: 93599 | E15: 95196 | F15: 107090
A16: Income tax expense | B16: 2047639860 | C16: 3596322058 | D16: 3480574440 | E16: 3565244457 | F16: 3830869094
A17: Workers profit participation fund | B17: 510064512 | C17: 616755878 | D17: 526322070 | E17: 867481244 | F17: 802781404
A18: others | B18: 91420912 | D18: 55472332 | E18: 110378188 | F18: 29685266
B19: =SUM(B12:B18) -> 28428043662 | C19: =SUM(C12:C18) -> 32111449629 | D19: =SUM(D12:D18) -> 36413773813 | E19: =SUM(E12:E18) -> 38769930520 | F19: =SUM(F12:F18) -> 42184131718
A20: Net cash generated from operating activities | B20: =B10-B19 -> 9615280977 | C20: =C10-C19 -> 9545179874 | D20: =D10-D19 -> 10007012109 | E20: =E10-E19 -> 12391793271 | F20: =F10-F19 -> 10760771937
A22: Cash flows from investing activities
A23: Purchase of fixed assets | B23: -2657669483 | C23: -2576915168 | D23: -3167173807 | E23: -2048539921 | F23: -2042104801
A24: Disposal of fixed assets | B24: 66788805 | C24: 46769925 | D24: 49109965 | E24: 66594884 | F24: 60742370
A25: Pre-operating expenses | F25: -774363
A26: Investment | B26: -80310552 | C26: -569633173 | D26: -1709234747 | E26: 116427551 | F26: -2413257573
A27: Non controlling interest (Payments) | E27: -209054502
A28: Short term loan | B28: -1281324584 | C28: 2354849736 | D28: -3110589073 | E28: 376808344 | F28: -409767691
A29: Gain on sale of marketable securities | B29: 10983571 | C29: 57295584 | D29: 291936032 | E29: 99860413 | F29: -8120460
A30: Interest received | B30: 253117331 | C30: 587461554 | D30: 955580148 | E30: 1407175500 | F30: 2712143496
A31: Dividend received | B31: 47172498 | C31: 295466575 | D31: 295896484 | E31: 360040347 | F31: 234546484
A32: Net cash used in investing activities | B32: =SUM(B23:B31) -> -3641242414 | C32: =SUM(C23:C31) -> 195295033 | D32: =SUM(D23:D31) -> -6394474998 | E32: =SUM(E23:E31) -> 169312616 | F32: =SUM(F23:F31) -> -1866592538
A34: Cash flows from financing activities
A35: Long term loan repaid | B35: -309810998
A36: Short term bank loan decrease | B36: -2297884
A37: Dividend Paid | B37: -1662897456 | C37: -2494346184 | D37: -2400808200 | E37: -2654607924 | F37: -3313835557
A38: Net cash used in financing activities | B38: =SUM(B35:B37) -> -1975006338 | C38: =SUM(C35:C37) -> -2494346184 | D38: =SUM(D35:D37) -> -2400808200 | E38: =SUM(E35:E37) -> -2654607924 | F38: =SUM(F35:F37) -> -3313835557
A40: Increase in cash and cash equivalents | B40: =SUM(B20,B32,B38) -> 3999032225 | C40: =SUM(C20,C32,C38) -> 7246128723 | D40: 1211728911 | E40: =SUM(E20,E32,E38) -> 9906497963 | F40: =SUM(F20,F32,F38) -> 5580343842
A41: Cash and cash equivalents at the opening | B41: 4523522906 | C41: 8522555131 | D41: 15768683854 | E41: =D43 -> 16980412765 | F41: =E43 -> 26886910728
A43: CASH AND CASH EQUIVALENTS AT THE END OF THE YEAR | B43: =SUM(B40:B41) -> 8522555131 | C43: =SUM(C40:C41) -> 15768683854 | D43: =SUM(D40:D41) -> 16980412765 | E43: =SUM(E40:E41) -> 26886910728 | F43: =SUM(F40:F41) -> 32467254570

Sheet Relative Valuation
A1: SQUARE PHARMACEUTICALS LTD.
A2: RELATIVE VALUATION
B3: 2015-2016 | C3: 2016-2017 | D3: 2017-2018 | E3: 2018-2019 | F3: 2019-2020
A4: Margins
A5: Gross Margin | B5: ='Income Statement'!B9/'Income Statement'!B7 -> 0.48350788 | C5: ='Income Statement'!C9/'Income Statement'!C7 -> 0.49991 | D5: ='Income Statement'!D9/'Income Statement'!D7 -> 0.49337002 | E5: ='Income Statement'!E9/'Income Statement'!E7 -> 0.49830659 | F5: ='Income Statement'!F9/'Income Statement'!F7 -> 0.50875295
A6: Operating Margin | B6: ='Income Statement'!B14/'Income Statement'!B7 -> 0.32627886 | C6: ='Income Statement'!C14/'Income Statement'!C7 -> 0.33648079 | D6: ='Income Statement'!D14/'Income Statement'!D7 -> 0.32231293 | E6: ='Income Statement'!E14/'Income Statement'!E7 -> 0.32117379 | F6: ='Income Statement'!F14/'Income Statement'!F7 -> 0.32108897
A7: EBT Margin | B7: ='Income Statement'!B19/'Income Statement'!B7 -> 0.32966465 | C7: ='Income Statement'!C19/'Income Statement'!C7 -> 0.34871285 | D7: ='Income Statement'!D19/'Income Statement'!D7 -> 0.3492207 | E7: ='Income Statement'!E19/'Income Statement'!E7 -> 0.3556574 | F7: ='Income Statement'!F19/'Income Statement'!F7 -> 0.37050781
A9: Management Effectiveness
A10: Return on Assets | B10: ='Income Statement'!B31/'Balance Sheet'!B21 -> 0.20765025 | C10: ='Income Statement'!C31/'Balance Sheet'!C21 -> 0.20897291 | D10: ='Income Statement'!D31/'Balance Sheet'!D21 -> 0.18281954 | E10: ='Income Statement'!E31/'Balance Sheet'!E21 -> 0.17471192 | F10: ='Income Statement'!F31/'Balance Sheet'!F21 -> 0.15569592
A11: Return on Equity | B11: ='Income Statement'!B31/'Balance Sheet'!B32 -> 0.22684444 | C11: ='Income Statement'!C31/'Balance Sheet'!C32 -> 0.2239054 | D11: ='Income Statement'!D31/'Balance Sheet'!D32 -> 0.193749 | E11: ='Income Statement'!E31/'Balance Sheet'!E32 -> 0.18569034 | F11: ='Income Statement'!F31/'Balance Sheet'!F32 -> 0.16478783
A13: Liquidity Ratios
A14: Quick Ratio | B14: =('Balance Sheet'!B19-'Balance Sheet'!B15)/'Balance Sheet'!B45 -> 4.1977981 | C14: =('Balance Sheet'!C19-'Balance Sheet'!C15)/'Balance Sheet'!C45 -> 6.0079491 | D14: =('Balance Sheet'!D19-'Balance Sheet'!D15)/'Balance Sheet'!D45 -> 7.8174935 | E14: =('Balance Sheet'!E19-'Balance Sheet'!E15)/'Balance Sheet'!E45 -> 8.6391705 | F14: =('Balance Sheet'!F19-'Balance Sheet'!F15)/'Balance Sheet'!F45 -> 10.15972
A15: Cash Ratio | B15: ='Balance Sheet'!B18/'Balance Sheet'!B43 -> 3.1657441 | C15: ='Balance Sheet'!C18/'Balance Sheet'!C43 -> 6.6775598 | D15: ='Balance Sheet'!D18/'Balance Sheet'!D43 -> 7.7169646 | E15: ='Balance Sheet'!E18/'Balance Sheet'!E43 -> 9.0889378 | F15: ='Balance Sheet'!F18/'Balance Sheet'!F43 -> 10.04592
A17: Growth
A18: Net Income Growth | C18: =('Income Statement'!C40-'Income Statement'!B40)/'Income Statement'!B40 -> 0.19325413 | D18: =('Income Statement'!D40-'Income Statement'!C40)/'Income Statement'!C40 -> 0.020435755 | E18: =('Income Statement'!E40-'Income Statement'!D40)/'Income Statement'!D40 -> 0.12523529 | F18: =('Income Statement'!F40-'Income Statement'!E40)/'Income Statement'!E40 -> 0.010653677
A19: Operating Profit Growth | C19: =('Income Statement'!C14-'Income Statement'!B14)/'Income Statement'!B14 -> 0.13944568 | D19: =('Income Statement'!D14-'Income Statement'!C14)/'Income Statement'!C14 -> 0.039433593 | E19: =('Income Statement'!E14-'Income Statement'!D14)/'Income Statement'!D14 -> 0.10652632 | F19: =('Income Statement'!F14-'Income Statement'!E14)/'Income Statement'!E14 -> 0.041574991
A20: Revenue Growth | C20: =('Income Statement'!C7-'Income Statement'!B7)/'Income Statement'!B7 -> 0.10489825 | D20: =('Income Statement'!D7-'Income Statement'!C7)/'Income Statement'!C7 -> 0.085123816 | E20: =('Income Statement'!E7-'Income Statement'!D7)/'Income Statement'!D7 -> 0.11045093 | F20: =('Income Statement'!F7-'Income Statement'!E7)/'Income Statement'!E7 -> 0.041850158
A21: EPS Growth | C21: =('Income Statement'!C42-'Income Statement'!B42)/'Income Statement'!B42 -> 0.15659955 | D21: =('Income Statement'!D42-'Income Statement'!C42)/'Income Statement'!C42 -> 0.013539652 | E21: =('Income Statement'!E42-'Income Statement'!D42)/'Income Statement'!D42 -> 0.019720102 | F21: =('Income Statement'!F42-'Income Statement'!E42)/'Income Statement'!E42 -> -0.013100437
A22: Dividend Growth | C22: =(C28-B28)/B28 -> 0.5 | D22: =(D28-C28)/C28 -> -0.037500001 | E22: =(E28-D28)/D28 -> 0.10571429 | F22: =(F28-E28)/E28 -> 0.24833333
A24: Cash Flow
A25: Operating Cash Flow Growth | C25: =('Cashflow Statement'!C20-'Cashflow Statement'!B20)/'Cashflow Statement'!B20 -> -0.0072905933 | D25: =('Cashflow Statement'!D20-'Cashflow Statement'!C20)/'Cashflow Statement'!C20 -> 0.048383817 | E25: =('Cashflow Statement'!E20-'Cashflow Statement'!D20)/'Cashflow Statement'!D20 -> 0.23831101 | F25: =('Cashflow Statement'!F20-'Cashflow Statement'!E20)/'Cashflow Statement'!E20 -> -0.13162109
A27: Dividends
A28: Dividends Paid | B28: =-'Cashflow Statement'!B37 -> 1662897456 | C28: =-'Cashflow Statement'!C37 -> 2494346184 | D28: =-'Cashflow Statement'!D37 -> 2400808200 | E28: =-'Cashflow Statement'!E37 -> 2654607924 | F28: =-'Cashflow Statement'!F37 -> 3313835557
A29: Dividend Payout Rate | B29: ='Relative Valuation'!B28/'Income Statement'!B40 -> 0.18075583 | C29: ='Relative Valuation'!C28/'Income Statement'!C40 -> 0.22722214 | D29: ='Relative Valuation'!D28/'Income Statement'!D40 -> 0.21432148 | E29: ='Relative Valuation'!E28/'Income Statement'!E40 -> 0.21060335 | F29: ='Relative Valuation'!F28/'Income Statement'!F40 -> 0.26013183
G31: =IF(ISBLANK(F31), "", AVERAGE(B31:F31))
G32: =IF(ISBLANK(F32), "", AVERAGE(B32:F32))
G33: =IF(ISBLANK(F33), "", AVERAGE(B33:F33))
G34: =IF(ISBLANK(F34), "", AVERAGE(B34:F34))
G35: =IF(ISBLANK(F35), "", AVERAGE(B35:F35))

Sheet EBV
B1: SQUARE PHARMACEUTICALS LTD.
B2: Consolidated Statement of Financial Position
B3: For the year ended 30 June 2020
B5: ASSETS | E5: EQUITY & LIABILITIES
B6: Non-current assets | E6: ='Balance Sheet'!A24 -> Share capital | F6: ='Balance Sheet'!F24 -> 8442390580
B7: ='Balance Sheet'!A6 -> Property, plant and equipment - Carrying Value | C7: ='Balance Sheet'!F6 -> 20873698301 | E7: ='Balance Sheet'!A25 -> Share premium | F7: ='Balance Sheet'!F25 -> 2035465000
B8: ='Balance Sheet'!A7 -> Investment - long term | C8: ='Balance Sheet'!F7 -> 2792000884 | E8: ='Balance Sheet'!A26 -> General Reserve | F8: ='Balance Sheet'!F26 -> 105878200
B9: ='Balance Sheet'!A8 -> Investment - associates undertaking | C9: ='Balance Sheet'!F8 -> 8077472192 | E9: ='Balance Sheet'!A27 -> Tax Exemption Reserve | F9: ='Balance Sheet'!F27 -> 2211743936
B10: ='Balance Sheet'!A9 -> Investment in marketable securities (Fair Value) | C10: ='Balance Sheet'!F9 -> 2691892867 | E10: ='Balance Sheet'!A28 -> Gain on marketable securities (Unrealized) | F10: ='Balance Sheet'!F28 -> -452626946
B11: ='Balance Sheet'!A10 -> Pre-operating expenses | C11: ='Balance Sheet'!F10 -> 774363 | E11: ='Balance Sheet'!A29 -> Cumulative Translation Adujustment | F11: ='Balance Sheet'!F29 -> -18078434
B12: Total Non-current assets | C12: =SUM(C7:C11) -> 34435838607 | E12: ='Balance Sheet'!A30 -> Retained earnings | F12: ='Balance Sheet'!F30 -> 64981071577
E13: ='Balance Sheet'!A31 -> Non-controlling interests | F13: ='Balance Sheet'!F31 -> 0
B14: Current Assets | E14: Total Equity | F14: =SUM(F6:F13) -> 77305843913
B15: ='Balance Sheet'!A14 -> Inventories | C15: ='Balance Sheet'!F14 -> 5687406329
B16: ='Balance Sheet'!A15 -> Trade and other receivables | C16: ='Balance Sheet'!F15 -> 1520300337 | E16: Non-current liability
B17: ='Balance Sheet'!A16 -> Advances, deposits and prepayments | C17: ='Balance Sheet'!F16 -> 2727928252 | E17: ='Balance Sheet'!A35 -> Deferred tax liability | F17: ='Balance Sheet'!F35 -> 1272750021
B18: ='Balance Sheet'!A17 -> Short Term Loan | C18: ='Balance Sheet'!F17 -> 4884338757 | E18: Total Non-current liability | F18: =F17 -> 1272750021
B19: ='Balance Sheet'!A18 -> Cash and cash equivalents | C19: ='Balance Sheet'!F18 -> 32564329438
B20: Total current assets | C20: =SUM(C15:C19) -> 47384303113 | E20: Current liability
E21: ='Balance Sheet'!A39 -> Short term loan | F21: ='Balance Sheet'!F39 -> 0
E22: ='Balance Sheet'!A40 -> Trade creditors | F22: ='Balance Sheet'!F40 -> 553785496
E23: ='Balance Sheet'!A41 -> Liabilities for expenses | F23: ='Balance Sheet'!F41 -> 128998444
E24: ='Balance Sheet'!A42 -> Liabilities for other finances | F24: ='Balance Sheet'!F42 -> 2558763846
E25: Total Current liability | F25: =SUM(F21:F24) -> 3241547786
E33: Total Liability | F33: =SUM(F18,F25) -> 4514297807
B35: TOTAL ASSETS | C35: =SUM(C12,C20) -> 81820141720 | E35: TOTAL EQUITY AND LIABILITY | F35: =SUM(F14,F33) -> 81820141720
H36: Calculations for EBV
H37: Step 1 | I37: Cash & Cash Equivalents | J37: =C19 -> 32564329438
B38: SQUARE PHARMACEUTICALS LTD. | H38: Step 2 | I38: Current Operating Liabilities | J38: =SUM(J39:J40) -> 1922848521
B39: ENTERPRISE BOOK VALUE | I39: Trade Payables | J39: =F22 -> 553785496
B40: JUNE 30 2020 | I40: Other Payables | J40: =368968264+18346013+3711211+978037537 -> 1369063025
B41: ASSETS | C41: BDT | E41: EQUITY AND LIABILITIES | F41: BDT | H41: Step 3 | I41: Net Working Capital | J41: =J42-J38 -> 8012786397
I42: Current Operating Assets | J42: =C15+C16+C17 -> 9935634918
B43: Net Working Capital | C43: =J41 -> 8012786397 | E43: Total Equity | F43: =F14 -> 77305843913 | H43: Step 4 | I43: Total Financial Debt | J43: =F18+F21+F23+(F24-J40) -> 2591449286
H44: Step 5 | I44: Net Financial Debt | J44: =J43-J37 -> -29972880152
B45: Non-Operating Current Assets | C45: =C18 -> 4884338757 | E45: Net Financial Debt | F45: =J44 -> -29972880152
B47: Non-Current Assets | C47: =C12 -> 34435838607
B49: Enterprise Book Value | C49: =SUM(C43:C47) -> 47332963761 | E49: Enterprise Book Value | F49: =SUM(F43:F46) -> 47332963761
B57: Enterprise Book Value | C57: =C49 -> 47332963761
B58: Number of Ordinary Shares | C58: 844239058
...

Sheet EMV
B2: SQUARE PHARMACEUTICALS LTD.
B3: ENTERPRISE MARKET VALUE
B4: July 6th, 2021
B6: Net Working Capital | C6: =EBV!C43 -> 8012786397 | E6: Net Financial Debt | F6: =EBV!J44 -> -29972880152
B8: Fixed Assets & Intangibles (EMV-NWC) | C8: =F10-C6 -> 1.4597402e+11 | E8: Market Capitalization | F8: =C14*C16 -> 1.8395969e+11
B10: Enterprise Market Value | C10: =C6+C8 -> 1.5398681e+11 | E10: Enterprise Market Value | F10: =SUM(F6:F8) -> 1.5398681e+11
B14: Share Price as of July 06, 2021 | C14: 217.9
B15: Enterprise Market Value | C15: =F10 -> 1.5398681e+11
B16: Number of Ordinary Shares | C16: =EBV!C58 -> 844239058
B17: EMV per share | C17: =C15/C16 -> 182.39716
B21: EBV per share | C21: =EBV!C59 -> 56.06583 | D21: < | E21: EMV per share | F21: =C17 -> 182.39716

Sheet Implied Cost of Debt
C4: TFD & NFD
D6: 2016 | E6: 2017 | F6: 2018 | G6: 2019 | H6: 2020
C7: Total Debt | D7: ='Balance Sheet'!B45 -> 3746615793 | E7: ='Balance Sheet'!C45 -> 3490677898 | F7: ='Balance Sheet'!D45 -> 3431533644 | G7: ='Balance Sheet'!E45 -> 4265435402 | H7: ='Balance Sheet'!F45 -> 4514297807
C8: Total Operating current liability | D8: ='Balance Sheet'!B40+(364347268+51559622+7696415+888297299) -> 2005883302 | E8: ='Balance Sheet'!C40+(493022685+60176480+7114330+241126028) -> 1645376800 | F8: ='Balance Sheet'!D40+(446877055+56596629+3619330+215699760) -> 1247468910 | G8: ='Balance Sheet'!E40+(641736368+8948030+2819514+557901454) -> 1928393794 | H8: =EBV!J38 -> 1922848521
C9: Total Financial Debt | D9: =D7-D8 -> 1740732491 | E9: =E7-E8 -> 1845301098 | F9: =F7-F8 -> 2184064734 | G9: =G7-G8 -> 2337041608 | H9: =H7-H8 -> 2591449286
C10: Cash and Cash Equivalents | D10: ='Balance Sheet'!B18 -> 8522555131 | E10: ='Balance Sheet'!C18 -> 15768683854 | F10: ='Balance Sheet'!D18 -> 16980412765 | G10: ='Balance Sheet'!E18 -> 27004038946 | H10: ='Balance Sheet'!F18 -> 32564329438
C11: Net Financial Debt | D11: =D9-D10 -> -6781822640 | E11: =E9-E10 -> -13923382756 | F11: =F9-F10 -> -14796348031 | G11: =G9-G10 -> -24666997338 | H11: =H9-H10 -> -29972880152
E14: Market Value of Debt
D15: 2016 | E15: 2017 | F15: 2018 | G15: 2019 | H15: 2020
C16: Net Financial Debt | D16: =D11 -> -6781822640 | E16: =E11 -> -13923382756 | F16: =F11 -> -14796348031 | G16: =G11 -> -24666997338 | H16: =H11 -> -29972880152
C17: Interest Expense | D17: ='Income Statement'!B13 -> -5299871 | E17: ='Income Statement'!C13 -> -154389 | F17: ='Income Statement'!D13 -> -93599 | G17: ='Income Statement'!E13 -> -95196 | H17: ='Income Statement'!F13 -> -107090
C18: Cost of debt | E18: =E17/AVERAGE(D16,E16) -> 1.4913061e-05 | F18: =F17/AVERAGE(E16,F16) -> 6.5180973e-06 | G18: =G17/AVERAGE(F16,G16) -> 4.8245276e-06 | H18: =H17/AVERAGE(G16,H16) -> 3.9198477e-06
C19: Weights | E19: 0.15 | F19: 0.2 | G19: 0.3 | H19: 0.35
C20: Weighted Average Cost of Debt | F20: =(E18*E19)+(F18*F19)+(G18*G19)+(H18*H19) -> 6.3598837e-06
E22: Book Value of Debt
D23: 2016 | E23: 2017 | F23: 2018 | G23: 2019 | H23: 2020
C24: Total Financial Debt | D24: =D9 -> 1740732491 | E24: =E9 -> 1845301098 | F24: =F9 -> 2184064734 | G24: =G9 -> 2337041608 | H24: =H9 -> 2591449286
C25: Interest Expense | D25: =D17 -> -5299871 | E25: =E17 -> -154389 | F25: =F17 -> -93599 | G25: =G17 -> -95196 | H25: =H17 -> -107090
C26: Interest Rate Paid | E26: =E25/AVERAGE(D24,E24) -> -8.6105719e-05 | F26: =F25/AVERAGE(E24,F24) -> -4.6458427e-05 | G26: =G25/AVERAGE(F24,G24) -> -4.2111816e-05 | H26: =H25/AVERAGE(G24,H24) -> -4.3457522e-05
C27: Weights | E27: 0.15 | F27: 0.2 | G27: 0.3 | H27: 0.35
C28: Implied Rate of interest | F28: =E26*E27+F26*F27+G26*G27+H26*H27 -> -5.0051221e-05
C32: Commercial Rate of Interest | D32: 0.09
C36: Implied Commercial Rate of Interest | D36: =D32+2% -> 0.11 | E36: 1
C37: Weighted Average Cost of Debt | D37: =F20 -> 6.3598837e-06 | E37: 0
C38: Implied Cost of Debt | E38: =(D37*E37+D36*E36) -> 0.11

Sheet Implied Cost of Equity (Gordon)
D5: 2016 | E5: 2017 | F5: 2018 | G5: 2019 | H5: 2020
C6: Cash Dividend paid | D6: =D12*D7 -> 2494346184 | E6: =E12*E7 -> 2400808200 | F6: =F12*F7 -> 2.6546079e+09 | G6: =G12*G7 -> 3.3138356e+09 | H6: =H12*H7 -> 3.9679236e+09
C7: Number of shares outstanding | D7: 623586546 | E7: 685945200 | F7: 737391090 | G7: 789008466 | H7: =EBV!C58 -> 844239058
C8: Total Equity Payout | D8: =-'Cashflow Statement'!B37 -> 1662897456 | E8: =-'Cashflow Statement'!C37 -> 2494346184 | F8: =-'Cashflow Statement'!D37 -> 2400808200 | G8: =-'Cashflow Statement'!E37 -> 2654607924 | H8: =-'Cashflow Statement'!F37 -> 3313835557
C9: Cash (%) | D9: 0.4 | E9: 0.35 | F9: 0.36 | G9: 0.42 | H9: 0.47
C10: Stock (%) | D10: 0.1 | E10: 0.075 | F10: 0.07 | G10: 0.07 | H10: 0.05
C11: Total (%) | D11: =SUM(D9:D10) -> 0.5 | E11: =SUM(E9:E10) -> 0.425 | F11: =SUM(F9:F10) -> 0.43 | G11: =SUM(G9:G10) -> 0.49 | H11: =SUM(H9:H10) -> 0.52
C12: Cash Dividend per share | D12: =10*D9 -> 4 | E12: =10*E9 -> 3.5 | F12: =10*F9 -> 3.6 | G12: =10*G9 -> 4.2 | H12: =10*H9 -> 4.7
C13: Stock Dividend per Share | D13: =10*D10 -> 1 | E13: =10*E10 -> 0.75 | F13: =10*F10 -> 0.7 | G13: =10*G10 -> 0.7 | H13: =10*H10 -> 0.5
C14: Dividend per Share | D14: =D12+D13 -> 5 | E14: =E12+E13 -> 4.25 | F14: =F12+F13 -> 4.3 | G14: =G12+G13 -> 4.9 | H14: =H12+H13 -> 5.2
C15: Dividend Growth Rate | E15: =(E14/D14)-1 -> -0.15 | F15: =(F14/E14)-1 -> 0.011764706 | G15: =(G14/F14)-1 -> 0.13953488 | H15: =(H14/G14)-1 -> 0.06122449
C18: Implied Dividend Growth Rate | D18: =(0.3*H15)+(0.4*G15)+(0.2*F15)+(0.1*E15) -> 0.061534242
E24: GORDON MODELS
D26: Gordon Growth Model | G26: All Cash Flows to Equity Model
D27: Share Price (06/07/21) | E27: 217.9 | G27: =D27 -> Share Price (06/07/21) | H27: =E27 -> 217.9
D28: Cash Dividend per share | E28: =H12 -> 4.7 | G28: Market capitalization | H28: =H27*H7 -> 1.8395969e+11
D29: Cost of equity | E29: =((E28*(1+D18))/E27)+D18 -> 0.084431033 | G29: Cost of Equity | H29: =((H8*(1+D18))/H28)+D18 -> 0.080656637
E33: Gordon Growth Model | F33: =E29 -> 0.084431033 | G33: 0.25
E34: All CFs to Equity Model | F34: =H29 -> 0.080656637 | G34: 0.75
E35: Implied Cost of Equity | G35: =(F34*G34+F33*G33) -> 0.081600236

Sheet Implied Cost of Equity (CAPM)
I3: DSEX
J4: 2017 | K4: 2018 | L4: 2019 | M4: 2020
I5: Average Monthly Return | J5: =AVERAGE(L86:L97) -> 0.01792352 | K5: =AVERAGE(L74:L85) -> -0.012330677 | L5: =AVERAGE(L62:L73) -> -0.01584782 | M5: =AVERAGE(L50:L61) -> 0.016101505
B6: Classical CAPM | E6: Tax Adjusted CAPM | I6: Annualized Returns | J6: =J5*12 -> 0.21508223 | K6: =K5*12 -> -0.14796813 | L6: =L5*12 -> -0.19017385 | M6: =M5*12 -> 0.19321806
B7: Risk Free Rate, Rf | C7: 0.0107 | E7: Risk Free Rate, Rf | F7: =C7*(1-F10) -> 0.0081017549 | I7: Weight Assigned | J7: 0.35 | K7: 0.1 | L7: 0.1 | M7: 0.45
B8: Beta, β | C8: =J15 -> 0.88 | E8: Beta, β | F8: =J15 -> 0.88 | I8: Expected Return on Market | L8: =(J7*J6)+(K7*K6)+(L7*L6)+(M7*M6) -> 0.12841271
B9: Return on the Market, Rm | C9: =L8 -> 0.12841271 | E9: Return on the Market, Rm | F9: =L8 -> 0.12841271
B10: Risk Premium | C10: =C9-C7 -> 0.11771271 | E10: Average Tax Rate | F10: =WACC!D17 -> 0.24282664
B11: Cost of Equity | C11: =C7+(C8*C10) -> 0.11428718 | E11: Risk Premium | F11: =F9-F7 -> 0.12031095 | I11: Beta Calculated using DSEx | J11: =SLOPE(D50:D97,L50:L97) -> 0.93446958
E12: Cost of Equity | F12: =F7+(F8*F11) -> 0.1139754 | I12: Beta Calculated using DS30 | J12: =SLOPE(D50:D97,H50:H97) -> 0.9145856
I13: Lanka Bangla | J13: 0.8
I14: Amar Stock | J14: 0.88
C15: Implied Cost of Equity | E15: =F12 -> 0.1139754 | I15: BETA | J15: 0.88
B41: Square Pharmaceuticals Ltd. | F41: DS30 | J41: DSEx | N41: DS30
B42: Date | C42: Price | D42: Change % | F42: Date | G42: Price | H42: Change % | J42: Date | K42: Price | L42: Change % | O42: 2017 | P42: 2018 | Q42: 2019 | R42: 2020
B43: 44398 | C43: 214.8 | D43: =LN(C43/C44) -> -0.0032535469 | F43: 44398 | G43: 2231.54 | H43: =LN(G43/G44) -> 0.010437243 | J43: 44398 | K43: 6177.21 | L43: =LN(K43/K44) -> 0.0043365857 | N43: Average Monthly Return | O43: =AVERAGE(H86:H97) -> 0.019313104 | P43: =AVERAGE(H74:H85) -> -0.016158345 | Q43: =AVERAGE(H62:H73) -> -0.018113955 | R43: =AVERAGE(H50:H61) -> 0.02172031
B44: 44368 | C44: 215.5 | D44: =LN(C44/C45) -> 0.011668744 | F44: 44368 | G44: 2208.37 | H44: =LN(G44/G45) -> 0.0011598985 | J44: 44368 | K44: 6150.48 | L44: =LN(K44/K45) -> 0.026275123 | N44: Annualized Returns | O44: =O43*12 -> 0.23175725 | P44: =P43*12 -> -0.19390014 | Q44: =Q43*12 -> -0.21736746 | R44: =R43*12 -> 0.26064371
B45: 44337 | C45: 213 | D45: =LN(C45/C46) -> 0.0056497325 | F45: 44337 | G45: 2205.81 | H45: =LN(G45/G46) -> 0.043975654 | J45: 44337 | K45: 5990.98 | L45: =LN(K45/K46) -> 0.089221074 | N45: Weight Assigned | O45: 0.35 | P45: 0.1 | Q45: 0.1 | R45: 0.45
B46: 44307 | C46: 211.8 | D46: =LN(C46/C47) -> 0.074471225 | F46: 44307 | G46: 2110.91 | H46: =LN(G46/G47) -> 0.056775881 | J46: 44307 | K46: 5479.61 | L46: =LN(K46/K47) -> 0.037456378 | N46: Expected Return on Market | Q46: =(O45*O44)+(P45*P44)+(Q45*Q44)+(R45*R44) -> 0.15727795
B47: 44276 | C47: 196.6 | D47: =LN(C47/C48) -> -0.095957339 | F47: 44276 | G47: 1994.4 | H47: =LN(G47/G48) -> -0.030822709 | J47: 44276 | K47: 5278.16 | L47: =LN(K47/K48) -> -0.023708045
B48: 44248 | C48: 216.4 | D48: =LN(C48/C49) -> -0.06572197 | F48: 44248 | G48: 2056.83 | H48: =LN(G48/G49) -> -0.049122798 | J48: 44248 | K48: 5404.79 | L48: =LN(K48/K49) -> -0.044345169
B49: 44217 | C49: 231.1 | D49: =LN(C49/C50) -> 0.051498285 | F49: 44217 | G49: 2160.39 | H49: =LN(G49/G50) -> 0.095325918 | J49: 44217 | K49: 5649.86 | L49: =LN(K49/K50) -> 0.044850404
B50: 44550 | C50: 219.5 | D50: =LN(C50/C51) -> 0.1769601 | F50: 44550 | G50: 1963.96 | H50: =LN(G50/G51) -> 0.15177396 | J50: 44550 | K50: 5402.06 | L50: =LN(K50/K51) -> 0.10433551
B51: 44520 | C51: 183.9 | D51: =LN(C51/C52) -> -0.027090298 | F51: 44520 | G51: 1687.4 | H51: =LN(G51/G52) -> 0.0043177114 | J51: 44520 | K51: 4866.84 | L51: =LN(K51/K52) -> 0.0042705981
B52: 44489 | C52: 188.95 | D52: =LN(C52/C53) -> -0.027869458 | F52: 44489 | G52: 1680.13 | H52: =LN(G52/G53) -> -0.0093954698 | J52: 44489 | K52: 4846.1 | L52: =LN(K52/K53) -> -0.02389457
B53: 44459 | C53: 194.29 | D53: =LN(C53/C54) -> -0.070491225 | F53: 44459 | G53: 1695.99 | H53: =LN(G53/G54) -> -0.0020909851 | J53: 44459 | K53: 4963.29 | L53: =LN(K53/K54) -> 0.017099852
B54: 44428 | C54: 208.48 | D54: =LN(C54/C55) -> 0.19014177 | F54: 44428 | G54: 1699.54 | H54: =LN(G54/G55) -> 0.17925719 | J54: 44428 | K54: 4879.14 | L54: =LN(K54/K55) -> 0.146457
B55: 44397 | C55: 172.38 | D55: =LN(C55/C56) -> 0.048068183 | F55: 44397 | G55: 1420.63 | H55: =LN(G55/G56) -> 0.057699745 | J55: 44397 | K55: 4214.42 | L55: =LN(K55/K56) -> 0.05495135
B56: 44367 | C56: 164.29 | D56: =LN(C56/C57) -> -0.094485355 | F56: 44367 | G56: 1340.98 | H56: =LN(G56/G57) -> -0.018024764 | J56: 44367 | K56: 3989.08 | L56: =LN(K56/K57) -> -0.017730714
B57: 44336 | C57: 180.57 | D57: =LN(C57/C58) -> 0.045721278 | F57: 44336 | G57: 1365.37 | H57: =LN(G57/G58) -> 0.025622646 | J57: 44336 | K57: 4060.44 | L57: =LN(K57/K58) -> 0.012929121
B58: 44306 | C58: 172.5 | D58: =LN(C58/C59) -> 0.048764078 | F58: 44306 | G58: 1330.83 | H58: =LN(G58/G59) -> 0 | J58: 44306 | K58: 4008.28 | L58: =LN(K58/K59) -> 0
... B137: 44452 | C137: 94.56 | D137: =LN(C137/C138) -> 0.023324049 | F137: 44452 | G137: 1440.52 | H137: =LN(G137/G138) -> -0.066791244 | J137: 44452 | K137: 3937.68 | L137: =LN(K137/K138) -> -0.047075334
B138: 44421 | C138: 92.38 | F138: 44421 | G138: 1540.02 | J138: 44421 | K138: 4127.48

Sheet WACC
B3: Market Price per Share | C3: =EMV!C14 -> 217.9 | I3: Calculations for WACC
B4: Number of Ordinary Shares | C4: =EMV!C16 -> 844239058 | I4: 1 | J4: Weight of Debt | K4: =C9/(C9+C5) -> -0.19464576
B5: Market Value of Equity | C5: =C3*C4 -> 1.8395969e+11 | I5: 2 | J5: Weight of Equity | K5: =C5/(C5+C9) -> 1.1946458
I6: 3 | J6: Implied Cost of Equity | K6: =D24 -> 0.10102533
B7: Total Financial Debt | C7: =EBV!J43 -> 2591449286 | I7: 4 | J7: Implied Cost of Debt | K7: ='Implied Cost of Debt'!E38 -> 0.11
B8: Cash & Cash Equivalents | C8: =EBV!J37 -> 32564329438 | I8: 5 | J8: Implied effective tax rate | K8: =D17 -> 0.24282664
B9: Market Value of Debt | C9: =C7-C8 -> -29972880152 | I9: WACC | K9: =(K5*K6)+((K4*K7)*(1-K8)) -> 0.10447762
B12: Implied Tax Rate
C13: 2016-17 | D13: 2017-18 | E13: 2018-19 | F13: 2019-20
B14: Net income before Tax | C14: ='Income Statement'!B19 -> 10903249640 | D14: ='Income Statement'!C19 -> 12743062576 | E14: ='Income Statement'!D19 -> 13847938760 | F14: ='Income Statement'!E19 -> 15660887890
B15: Income Tax | C15: =-'Income Statement'!B24 -> 2616706085 | D15: =-'Income Statement'!C24 -> 3023886371 | E15: =-'Income Statement'!D24 -> 3357047478 | F15: =-'Income Statement'!E24 -> 3940193051
B16: Income Tax Rate | C16: =C15/C14 -> 0.23999323 | D16: =D15/D14 -> 0.23729667 | E16: =E15/E14 -> 0.24242218 | F16: =F15/F14 -> 0.25159449
B17: Implied Tax Rate | D17: =AVERAGE(C16:F16) -> 0.24282664
B20: Cost of Equity
C21: Gordon Model | D21: CAPM
B22: Re | C22: ='Implied Cost of Equity (Gordon)'!G35 -> 0.081600236 | D22: ='Implied Cost of Equity (CAPM)'!E15 -> 0.1139754
B23: Weights assigned | C23: 0.4 | D23: 0.6
B24: Implied Average Cost of Equity | D24: =(C23*C22)+(D23*D22) -> 0.10102533

Sheet DCF (CCF)
B1: SQUARE PHARMACEUTICALS LTD.
B2: CONSOLIDATED CASH FLOW
C3: 2015-16 | D3: 2016-17 | E3: 2017-18 | F3: 2018-19 | G3: 2019-20
B4: Cash flows from operating activities
B5: Collection from customers and other income | C5: ='Cashflow Statement'!B10 -> 38043324639 | D5: ='Cashflow Statement'!C10 -> 41656629503 | E5: ='Cashflow Statement'!D10 -> 46420785922 | F5: ='Cashflow Statement'!E10 -> 51161723791 | G5: ='Cashflow Statement'!F10 -> 52944903655
B6: ='Cashflow Statement'!A12 -> Purchase of raw and packing materials | C6: =-'Cashflow Statement'!B12 -> -12055106675 | D6: =-'Cashflow Statement'!C12 -> -12448372527 | E6: =-'Cashflow Statement'!D12 -> -14895596440 | F6: =-'Cashflow Statement'!E12 -> -15619769171 | G6: =-'Cashflow Statement'!F12 -> -17024316320
B7: ='Cashflow Statement'!A13 -> Manufacturing and operating expenses | C7: =-'Cashflow Statement'!B13 -> -8466672238 | D7: =-'Cashflow Statement'!C13 -> -9708309353 | E7: =-'Cashflow Statement'!D13 -> -11222587267 | F7: =-'Cashflow Statement'!E13 -> -11773729181 | G7: =-'Cashflow Statement'!F13 -> -13446602730
B8: ='Cashflow Statement'!A14 -> Value added tax | C8: =-'Cashflow Statement'!B14 -> -5251839594 | D8: =-'Cashflow Statement'!C14 -> -5741535424 | E8: =-'Cashflow Statement'!D14 -> -6233127665 | F8: =-'Cashflow Statement'!E14 -> -6833233083 | G8: =-'Cashflow Statement'!F14 -> -7049769814
B9: ='Cashflow Statement'!A15 -> Finance Cost | C9: =-'Cashflow Statement'!B15 -> -5299871 | D9: =-'Cashflow Statement'!C15 -> -154389 | E9: =-'Cashflow Statement'!D15 -> -93599 | F9: =-'Cashflow Statement'!E15 -> -95196 | G9: =-'Cashflow Statement'!F15 -> -107090
B10: ='Cashflow Statement'!A16 -> Income tax expense | C10: =-'Cashflow Statement'!B16 -> -2047639860 | D10: =-'Cashflow Statement'!C16 -> -3596322058 | E10: =-'Cashflow Statement'!D16 -> -3480574440 | F10: =-'Cashflow Statement'!E16 -> -3565244457 | G10: =-'Cashflow Statement'!F16 -> -3830869094
B11: ='Cashflow Statement'!A17 -> Workers profit participation fund | C11: =-'Cashflow Statement'!B17 -> -510064512 | D11: =-'Cashflow Statement'!C17 -> -616755878 | E11: =-'Cashflow Statement'!D17 -> -526322070 | F11: =-'Cashflow Statement'!E17 -> -867481244 | G11: =-'Cashflow Statement'!F17 -> -802781404
B12: ='Cashflow Statement'!A18 -> others | C12: =-'Cashflow Statement'!B18 -> -91420912 | D12: =-'Cashflow Statement'!C18 -> 0 | E12: =-'Cashflow Statement'!D18 -> -55472332 | F12: =-'Cashflow Statement'!E18 -> -110378188 | G12: =-'Cashflow Statement'!F18 -> -29685266
B14: Net cash generated from operating activities | C14: =SUM(C5:C12) -> 9615280977 | D14: =SUM(D5:D12) -> 9545179874 | E14: =SUM(E5:E12) -> 10007012109 | F14: =SUM(F5:F12) -> 12391793271 | G14: =SUM(G5:G12) -> 10760771937
B16: Cash flows from investing activities
B17: ='Cashflow Statement'!A23 -> Purchase of fixed assets | C17: ='Cashflow Statement'!B23 -> -2657669483 | D17: ='Cashflow Statement'!C23 -> -2576915168 | E17: ='Cashflow Statement'!D23 -> -3167173807 | F17: ='Cashflow Statement'!E23 -> -2048539921 | G17: ='Cashflow Statement'!F23 -> -2042104801
B18: ='Cashflow Statement'!A24 -> Disposal of fixed assets | C18: ='Cashflow Statement'!B24 -> 66788805 | D18: ='Cashflow Statement'!C24 -> 46769925 | E18: ='Cashflow Statement'!D24 -> 49109965 | F18: ='Cashflow Statement'!E24 -> 66594884 | G18: ='Cashflow Statement'!F24 -> 60742370
B20: Net cash used in investing activities | C20: =SUM(C17:C18) -> -2590880678 | D20: =SUM(D17:D18) -> -2530145243 | E20: =SUM(E17:E18) -> -3118063842 | F20: =SUM(F17:F18) -> -1981945037 | G20: =SUM(G17:G18) -> -1981362431
B23: Tax Rate | C23: =-'Income Statement'!B24/'Income Statement'!B19 -> 0.23999323 | D23: =-'Income Statement'!C24/'Income Statement'!C19 -> 0.23729667 | E23: =-'Income Statement'!D24/'Income Statement'!D19 -> 0.24242218 | F23: =-'Income Statement'!E24/'Income Statement'!E19 -> 0.25159449 | G23: =-'Income Statement'!F24/'Income Statement'!F19 -> 0.24882411
B25: After tax interest | C25: =(1-C23)*-'Income Statement'!B13 -> 4027937.8 | D25: =(1-D23)*-'Income Statement'!C13 -> 117753 | E25: =(1-E23)*-'Income Statement'!D13 -> 70908.527 | F25: =(1-F23)*-'Income Statement'!E13 -> 71245.211 | G25: =(1-G23)*-'Income Statement'!F13 -> 80443.426
B26: FCF | C26: =C14+C20+C25 -> 7.0284282e+09 | D26: =D14+D20+D25 -> 7.0151524e+09 | E26: =E14+E20+E25 -> 6.8890192e+09 | F26: =F14+F20+F25 -> 1.0409919e+10 | G26: =G14+G20+G25 -> 8.7794899e+09
B27: Short term growth | D27: =(D26-C26)/C26 -> -0.0018888793 | E27: =(E26-D26)/D26 -> -0.01798011 | F27: =(F26-E26)/E26 -> 0.51108877 | G27: =(G26-F26)/F26 -> -0.15662268
B28: Weights | D28: 0.25 | E28: 0.23 | F28: 0.37 | G28: 0.15
B29: Implied short term growth rate | C29: =D28*D27+E28*E27+F28*F27+G28*G27 -> 0.1610018
C32: 2021 | D32: 2022 | E32: 2023 | F32: 2024
B33: FCF | C33: =G26*(1+C29) -> 1.0193004e+10 | D33: =C33*(1+C29) -> 1.1834095e+10 | E33: =D33*(1+C29) -> 1.3739406e+10 | F33: =E33*(1+C29) -> 1.5951475e+10
B34: Terminal Value | F34: =F33*((1+F39)/(F41-F39)) -> 3.8015891e+11
B35: Total | C35: =C33+C34 -> 1.0193004e+10 | D35: =D33+D34 -> 1.1834095e+10 | E35: =E33+E34 -> 1.3739406e+10 | F35: =F33+F34 -> 3.9611039e+11
B38: Enterprise Value | C38: =NPV(F41,C35:F35)*(1+F41)^0.5 -> 3.1035929e+11 | E38: Short-term growth rate | F38: =C29 -> 0.1610018
B39: =EMV!B14 -> Share Price as of July 06, 2021 | C39: =EMV!C14 -> 217.9 | E39: Long-term FCF growth rate | F39: 0.06
B40: Enterprise Value per share | C40: =C38/F40 -> 367.62016 | E40: Number of shares | F40: =EBV!C58 -> 844239058
E41: WACC | F41: =WACC!K9 -> 0.10447762

Sheet DCF (Pro-forma)
B2: Pro-forma Model
B3: Pro-forma Ratios
C4: 2016 | D4: 2017 | E4: 2018 | F4: 2019 | G4: 2020 | H4: Implied Rates
B5: Sales growth | D5: =('Income Statement'!C7/'Income Statement'!B7)-1 -> 0.10489825 | E5: =('Income Statement'!D7/'Income Statement'!C7)-1 -> 0.085123816 | F5: =('Income Statement'!E7/'Income Statement'!D7)-1 -> 0.11045093 | G5: =('Income Statement'!F7/'Income Statement'!E7)-1 -> 0.041850158 | H5: =(0.3*D5)+(0.15*E5)+(0.45*F5)+(0.1*G5) -> 0.098125982
B6: Current Assets | D6: =('Balance Sheet'!C19/'Balance Sheet'!B19)-1 -> 0.35822142 | E6: =('Balance Sheet'!D19/'Balance Sheet'!C19)-1 -> 0.2272068 | F6: =('Balance Sheet'!E19/'Balance Sheet'!D19)-1 -> 0.35054737 | G6: =('Balance Sheet'!F19/'Balance Sheet'!E19)-1 -> 0.23359223 | H6: =(0.3*D6)+(0.2*E6)+(0.4*F6)+(0.1*G6) -> 0.31648596
B7: Net Fixed Assets | D7: =('Balance Sheet'!C11/'Balance Sheet'!B11)-1 -> 0.077635395 | E7: =('Balance Sheet'!D11/'Balance Sheet'!C11)-1 -> 0.11841992 | F7: =('Balance Sheet'!E11/'Balance Sheet'!D11)-1 -> 0.027502435 | G7: =('Balance Sheet'!F11/'Balance Sheet'!E11)-1 -> 0.020792658 | H7: =(0.3*D7)+(0.3*E7)+(0.3*F7)+(0.1*G7) -> 0.069146591
B8: Depreciation Rate | C8: =C30/'Balance Sheet'!B6 -> 0.10668778 | D8: =D30/'Balance Sheet'!C6 -> 0.10191666 | E8: =E30/'Balance Sheet'!D6 -> 0.097244736 | F8: =F30/'Balance Sheet'!E6 -> 0.097234136 | G8: =G30/'Balance Sheet'!F6 -> 0.094383182 | H8: =(0.1*D8)+(0.2*E8)+(0.4*F8)+(0.3*G8) -> 0.096849222
B9: Property, plant and equipment | D9: =('Balance Sheet'!C6/'Balance Sheet'!B6)-1 -> 0.025216411 | E9: =('Balance Sheet'!D6/'Balance Sheet'!C6)-1 -> 0.063232083 | F9: =('Balance Sheet'!E6/'Balance Sheet'!D6)-1 -> 0.015016406 | G9: =('Balance Sheet'!F6/'Balance Sheet'!E6)-1 -> 0.00094668037 | H9: =(0.2*D9)+(0.3*E9)+(0.3*F9)+(0.2*G9) -> 0.028707165
B10: Inventory | D10: =('Balance Sheet'!C14/'Balance Sheet'!B14)-1 -> 0.0097699534 | E10: =('Balance Sheet'!D14/'Balance Sheet'!C14)-1 -> 0.18819699 | F10: =('Balance Sheet'!E14/'Balance Sheet'!D14)-1 -> 0.036900507 | G10: =('Balance Sheet'!F14/'Balance Sheet'!E14)-1 -> 0.23733072 | H10: =(0.2*D10)+(0.3*E10)+(0.3*F10)+(0.2*G10) -> 0.11694938
B11: Trade and other receivables | D11: =('Balance Sheet'!C40/'Balance Sheet'!B40)-1 -> 0.21607827 | E11: =('Balance Sheet'!D40/'Balance Sheet'!C40)-1 -> -0.37829961 | F11: =('Balance Sheet'!E40/'Balance Sheet'!D40)-1 -> 0.36653524 | G11: =('Balance Sheet'!F40/'Balance Sheet'!E40)-1 -> -0.22762283 | H11: =(0.2*D11)+(0.2*E11)+(0.4*F11)+(0.2*G11) -> 0.068645262
B12: Long-term Investment/Total Other Non-current Assets | C12: ='Balance Sheet'!B7/'Balance Sheet'!B11 -> 0.020406229 | D12: ='Balance Sheet'!C7/'Balance Sheet'!C11 -> 0.020058052 | E12: ='Balance Sheet'!D7/'Balance Sheet'!D11 -> 0.028654048 | F12: ='Balance Sheet'!E7/'Balance Sheet'!E11 -> 0.01942849 | G12: ='Balance Sheet'!F7/'Balance Sheet'!F11 -> 0.081078347 | H12: =AVERAGE(C12:G12) -> 0.033925033
B13: Investment in marketable securities/Other Non-current Assets | C13: ='Balance Sheet'!B9/('Balance Sheet'!B6+'Balance Sheet'!B7+'Balance Sheet'!B8) -> 0.040954911 | D13: ='Balance Sheet'!C9/('Balance Sheet'!C6+'Balance Sheet'!C7+'Balance Sheet'!C8) -> 0.070693663 | E13: ='Balance Sheet'!D9/('Balance Sheet'!D6+'Balance Sheet'!D7+'Balance Sheet'!D8) -> 0.096565923 | F13: ='Balance Sheet'!E9/('Balance Sheet'!E6+'Balance Sheet'!E7+'Balance Sheet'!E8) -> 0.098090642 | G13: ='Balance Sheet'!F9/('Balance Sheet'!F6+'Balance Sheet'!F7+'Balance Sheet'!F8) -> 0.084802266 | H13: =AVERAGE(C13:G13) -> 0.078221481
B14: Advances, deposits and prepayments | D14: =('Balance Sheet'!C16/'Balance Sheet'!B16)-1 -> 0.28249334 | E14: =('Balance Sheet'!D16/'Balance Sheet'!C16)-1 -> 0.57185954 | F14: =('Balance Sheet'!E16/'Balance Sheet'!D16)-1 -> 0.013825961 | G14: =('Balance Sheet'!F16/'Balance Sheet'!E16)-1 -> 0.1797971 | H14: =(0.2*D14)+(0.15*E14)+(0.15*F14)+(0.5*G14) -> 0.23425004
B15: Tax/Deferred Tax Liability | C15: =ABS('Income Statement'!B24/'Balance Sheet'!B35) -> 2.4814703 | D15: =ABS('Income Statement'!C24/'Balance Sheet'!C35) -> 2.6778212 | E15: =ABS('Income Statement'!D24/'Balance Sheet'!D35) -> 2.7267948 | F15: =ABS('Income Statement'!E24/'Balance Sheet'!E35) -> 3.0441554 | G15: =ABS('Income Statement'!F24/'Balance Sheet'!F35) -> 3.3230471 | H15: =AVERAGE(C15:G15) -> 2.8506578
B16: Debt/Equity | C16: =('Balance Sheet'!B39+'Balance Sheet'!B41+'Balance Sheet'!B42)/'Balance Sheet'!B32 -> 0.049269686 | D16: =('Balance Sheet'!C39+'Balance Sheet'!C41+'Balance Sheet'!C42)/'Balance Sheet'!C32 -> 0.030952029 | E16: =('Balance Sheet'!D39+'Balance Sheet'!D41+'Balance Sheet'!D42)/'Balance Sheet'!D32 -> 0.028983464 | F16: =('Balance Sheet'!E39+'Balance Sheet'!E41+'Balance Sheet'!E42)/'Balance Sheet'!E32 -> 0.03320683 | G16: =('Balance Sheet'!F39+'Balance Sheet'!F41+'Balance Sheet'!F42)/'Balance Sheet'!F32 -> 0.034767906 | H16: =(0.1*D16)+(0.2*E16)+(0.4*F16)+(0.3*G16) -> 0.032604999
B17: Short-term Loan Growth | D17: =(('Balance Sheet'!C39+'Balance Sheet'!C41+'Balance Sheet'!C42)/('Balance Sheet'!B39+'Balance Sheet'!B41+'Balance Sheet'!B42))-1 -> -0.24053835 | E17: =(('Balance Sheet'!D39+'Balance Sheet'!D41+'Balance Sheet'!D42)/('Balance Sheet'!C39+'Balance Sheet'!C41+'Balance Sheet'!C42))-1 -> 0.10426153 | F17: =(('Balance Sheet'!E39+'Balance Sheet'!E41+'Balance Sheet'!E42)/('Balance Sheet'!D39+'Balance Sheet'!D41+'Balance Sheet'!D42))-1 -> 0.34514969 | G17: =(('Balance Sheet'!F39+'Balance Sheet'!F41+'Balance Sheet'!F42)/('Balance Sheet'!E39+'Balance Sheet'!E41+'Balance Sheet'!E42))-1 -> 0.19238817 | H17: =(0.05*D17)+(0.15*G17)+(0.4*F17)+(0.3*E17) -> 0.18616964
B18: Trade Payables/Sales | C18: ='Balance Sheet'!B40/'Income Statement'!B7 -> 0.020982878 | D18: ='Balance Sheet'!C40/'Income Statement'!C7 -> 0.023094274 | E18: ='Balance Sheet'!D40/'Income Statement'!D7 -> 0.013231411 | F18: ='Balance Sheet'!E40/'Income Statement'!E7 -> 0.016282745 | G18: ='Balance Sheet'!F40/'Income Statement'!F7 -> 0.012071237 | H18: =(0.1*D18)+(0.2*E18)+(0.4*F18)+(0.3*G18) -> 0.015090179
B19: Cost of Goods/Sales | C19: =ABS('Income Statement'!B8/'Income Statement'!B7) -> 0.51649212 | D19: =ABS('Income Statement'!C8/'Income Statement'!C7) -> 0.50009 | E19: =ABS('Income Statement'!D8/'Income Statement'!D7) -> 0.50662998 | F19: =ABS('Income Statement'!E8/'Income Statement'!E7) -> 0.50169341 | G19: =ABS('Income Statement'!F8/'Income Statement'!F7) -> 0.49124705 | H19: =(0.1*D19)+(0.2*E19)+(0.4*F19)+(0.3*G19)-20% -> 0.29938648
B20: Operating Expenses/Sales | C20: ='Cashflow Statement'!B19/'Income Statement'!B7 -> 0.85953466 | D20: ='Cashflow Statement'!C19/'Income Statement'!C7 -> 0.87872716 | E20: ='Cashflow Statement'!D19/'Income Statement'!D7 -> 0.91829143 | F20: ='Cashflow Statement'!E19/'Income Statement'!E7 -> 0.88046175 | G20: ='Cashflow Statement'!F19/'Income Statement'!F7 -> 0.91951607 | H20: =(0.2*D20)+(0.2*E20)+(0.3*F20)+(0.3*G20)-35% -> 0.54939706
B21: Other Income/Investment in Shares | C21: ='Income Statement'!B16/'Balance Sheet'!B9 -> 0.61315815 | D21: ='Income Statement'!C16/'Balance Sheet'!C9 -> 0.56421964 | E21: ='Income Statement'!D16/'Balance Sheet'!D9 -> 0.6115415 | F21: ='Income Statement'!E16/'Balance Sheet'!E9 -> 0.76668535 | G21: ='Income Statement'!F16/'Balance Sheet'!F9 -> 1.1614244 | H21: =(0.1*D21)+(0.2*E21)+(0.3*F21)+(0.4*G21) -> 0.87330563
B22: FInance Costs | C22: =ABS('Income Statement'!B13/('Balance Sheet'!B39+'Balance Sheet'!B41+'Balance Sheet'!B42)) -> 0.0026524091 | D22: =ABS('Income Statement'!C13/('Balance Sheet'!C39+'Balance Sheet'!C41+'Balance Sheet'!C42)) -> 0.00010173859 | E22: =ABS('Income Statement'!D13/('Balance Sheet'!D39+'Balance Sheet'!D41+'Balance Sheet'!D42)) -> 5.5855845e-05 | F22: =ABS('Income Statement'!E13/('Balance Sheet'!E39+'Balance Sheet'!E41+'Balance Sheet'!E42)) -> 4.2232375e-05 | G22: =ABS('Income Statement'!F13/('Balance Sheet'!F39+'Balance Sheet'!F41+'Balance Sheet'!F42)) -> 3.9843553e-05 | H22: =(0.4*D22)+(0.2*E22)+(0.2*F22)+(0.2*G22) -> 6.8281791e-05
B23: WPPF/Sales | C23: =ABS('Income Statement'!B18/'Income Statement'!B7) -> 0.016483232 | D23: =ABS('Income Statement'!C18/'Income Statement'!C7) -> 0.017693544 | E23: =ABS('Income Statement'!D18/'Income Statement'!D7) -> 0.017680457 | F23: =ABS('Income Statement'!E18/'Income Statement'!E7) -> 0.01798447 | G23: =ABS('Income Statement'!F18/'Income Statement'!F7) -> 0.01873007 | H23: =(0.3*D23)+(0.2*E23)+(0.3*F23)+(0.2*G23) -> 0.017985509
B24: Tax Rate | C24: =ABS('Income Statement'!B24/'Income Statement'!B19) -> 0.23999323 | D24: =ABS('Income Statement'!C24/'Income Statement'!C19) -> 0.23729667 | E24: =ABS('Income Statement'!D24/'Income Statement'!D19) -> 0.24242218 | F24: =ABS('Income Statement'!E24/'Income Statement'!E19) -> 0.25159449 | G24: =ABS('Income Statement'!F24/'Income Statement'!F19) -> 0.24882411 | H24: =AVERAGE(D24:G24)-10% -> 0.14503436
B25: Dividend Payout Ratio | C25: =ABS('Cashflow Statement'!B37/'Income Statement'!B31) -> 0.18075583 | D25: =ABS('Cashflow Statement'!C37/'Income Statement'!C31) -> 0.22722214 | E25: =ABS('Cashflow Statement'!D37/'Income Statement'!D31) -> 0.21432148 | F25: =ABS('Cashflow Statement'!E37/'Income Statement'!E31) -> 0.21060335 | G25: =ABS('Cashflow Statement'!F37/'Income Statement'!F31) -> 0.26013183 | H25: =(0.1*D25)+(0.2*E25)+(0.4*F25)+(0.3*G25)+10% -> 0.3278674
B26: Dividend Growth Rate | D26: =(ABS('Cashflow Statement'!C37/'Cashflow Statement'!B37))-1 -> 0.5 | E26: =(ABS('Cashflow Statement'!D37/'Cashflow Statement'!C37))-1 -> -0.037500001 | F26: =(ABS('Cashflow Statement'!E37/'Cashflow Statement'!D37))-1 -> 0.10571429 | G26: =(ABS('Cashflow Statement'!F37/'Cashflow Statement'!E37))-1 -> 0.24833333 | H26: =(0.1*D26)+(0.2*E26)+(0.3*F26)+(0.4*G26) -> 0.17354762
C29: 2016 | D29: 2017 | E29: 2018 | F29: 2019 | G29: 2020
B30: Depreciation | C30: 2010881334 | D30: 1969393467 | E30: 1997935652 | F30: 2027716414 | G30: 1970126072
B33: SQUARE PHARMACEUTICALS LTD.
B34: Pro-forma Income statement
C35: 2020 | D35: 2021 | E35: 2022 | F35: 2023 | G35: 2024
B37: ='Income Statement'!A7 -> Net revenue | C37: ='Income Statement'!B7 -> 33073760572 | D37: =C37*(1+$H$5) -> 3.6319156e+10 | E37: =D37*(1+$H$5) -> 3.9883009e+10 | F37: =E37*(1+$H$5) -> 4.3796568e+10 | G37: =F37*(1+$H$5) -> 4.8094149e+10
B38: Cost of Goods sold | C38: ='Income Statement'!B8 -> -17082336657 | D38: =-D37*$H$19 -> -1.0873464e+10 | E38: =-E37*$H$19 -> -1.1940433e+10 | F38: =-F37*$H$19 -> -1.31121e+10 | G38: =-G37*$H$19 -> -1.4398738e+10
B39: Gross profit | C39: =SUM(C37:C38) -> 15991423915 | D39: =SUM(D37:D38) -> 2.5445692e+10 | E39: =SUM(E37:E38) -> 2.7942575e+10 | F39: =SUM(F37:F38) -> 3.0684468e+10 | G39: =SUM(G37:G38) -> 3.3695411e+10
B41: Operating Expenses | C41: ='Cashflow Statement'!B19 -> 28428043662 | D41: =D37*$H$20 -> 1.9953637e+10 | E41: =E37*$H$20 -> 2.1911608e+10 | F41: =F37*$H$20 -> 2.4061706e+10 | G41: =G37*$H$20 -> 2.6422784e+10
B42: Operating Profit | C42: =C39-C41 -> -12436619747 | D42: =D39-D41 -> 5.4920543e+09 | E42: =E39-E41 -> 6.0309675e+09 | F42: =F39-F41 -> 6.6227621e+09 | G42: =G39-G41 -> 7.2726271e+09
B44: Other Income | C44: ='Income Statement'!B16 -> 657143316 | D44: =D63*$H$21 -> 1.9283743e+10 | E44: =E63*$H$21 -> 1.9625683e+10 | F44: =F63*$H$21 -> 2.018188e+10 | G44: =G63*$H$21 -> 2.0761e+10
B45: Finance Costs | C45: ='Income Statement'!B13 -> -5299871 | D45: =-(D81*$H$22) -> -161836.51 | E45: =-(E81*$H$22) -> -191965.55 | F45: =-(F81*$H$22) -> -227703.71 | G45: =-(G81*$H$22) -> -270095.23
B46: Profit before contribution to WPPF | C46: =C44+C42+C45 -> -11784776302 | D46: =D44+D42+D45 -> 2.4775635e+10 | E46: =E44+E42+E45 -> 2.5656459e+10 | F46: =F44+F42+F45 -> 2.6804415e+10 | G46: =G44+G42+G45 -> 2.8033357e+10
B48: Contribution to WPPF | C48: ='Income Statement'!B18 -> -545162482 | D48: =-(D37*$H$23) -> -6.5321852e+08 | E48: =-(E37*$H$23) -> -7.1731623e+08 | F48: =-(F37*$H$23) -> -7.8770358e+08 | G48: =-(G37*$H$23) -> -8.6499777e+08
B49: Profit before tax | C49: =SUM(C46,C48) -> -12329938784 | D49: =SUM(D46,D48) -> 2.4122417e+10 | E49: =SUM(E46,E48) -> 2.4939143e+10 | F49: =SUM(F46,F48) -> 2.6016711e+10 | G49: =SUM(G46,G48) -> 2.7168359e+10
...

Sheet Long Term GR 

Sheet Recommendation 
E2: DCF (Pro-forma) | H2: DCF (CCF)
E3: Enterprise Value | F3: ='DCF (Pro-forma)'!C111 -> 2.12961e+11 | H3: Enterprise Value | I3: ='DCF (CCF)'!C38 -> 3.1035929e+11
E4: ='DCF (Pro-forma)'!B112 -> Share Price as of July 06, 2021 | F4: ='DCF (Pro-forma)'!C112 -> 217.9 | H4: ='DCF (CCF)'!B39 -> Share Price as of July 06, 2021 | I4: ='DCF (CCF)'!C39 -> 217.9
E5: EV per share | F5: ='DCF (Pro-forma)'!C113 -> 252.25201 | H5: EV per share | I5: ='DCF (CCF)'!C40 -> 367.62016
F9: Target Price
G10: Weights | H10: Value per share
F11: DCF (CCF) | G11: 0.25 | H11: =I5*G11 -> 91.905039
F12: DCF (Pro-forma) | G12: 0.75 | H12: =F5*G12 -> 189.18901
F13: Target Price | H13: =H11+H12 -> 281.09405
F14: =H4 -> Share Price as of July 06, 2021 | H14: =I4 -> 217.9
F15: Upside Potential | H15: =(H13-H14)/H14 -> 0.29001398
